{
 "cells": [
  {
   "cell_type": "code",
   "execution_count": 7,
   "id": "b6313287-b931-4014-bdb0-1a8669d19ff9",
   "metadata": {},
   "outputs": [
    {
     "name": "stdout",
     "output_type": "stream",
     "text": [
      "creating network model using gpu 0\n",
      "--------------- SalsaNet model --------------------\n",
      "input (None, 64, 256, 4)\n",
      "logits (None, 64, 256, 3)\n",
      "- Restoring parameters from saved checkpoints\n",
      "  - D:\\train_salsanet_2\\logs\\salsaNet_trained\n",
      "INFO:tensorflow:Restoring parameters from D:\\train_salsanet_2\\logs\\salsaNet_trained\n"
     ]
    },
    {
     "ename": "DataLossError",
     "evalue": "Graph execution error:\n\nDetected at node 'summary/saver/RestoreV2' defined at (most recent call last):\n    File \"C:\\Users\\mahdi\\anaconda3\\envs\\tf\\lib\\runpy.py\", line 197, in _run_module_as_main\n      return _run_code(code, main_globals, None,\n    File \"C:\\Users\\mahdi\\anaconda3\\envs\\tf\\lib\\runpy.py\", line 87, in _run_code\n      exec(code, run_globals)\n    File \"C:\\Users\\mahdi\\anaconda3\\envs\\tf\\lib\\site-packages\\ipykernel_launcher.py\", line 17, in <module>\n      app.launch_new_instance()\n    File \"C:\\Users\\mahdi\\anaconda3\\envs\\tf\\lib\\site-packages\\traitlets\\config\\application.py\", line 992, in launch_instance\n      app.start()\n    File \"C:\\Users\\mahdi\\anaconda3\\envs\\tf\\lib\\site-packages\\ipykernel\\kernelapp.py\", line 701, in start\n      self.io_loop.start()\n    File \"C:\\Users\\mahdi\\anaconda3\\envs\\tf\\lib\\site-packages\\tornado\\platform\\asyncio.py\", line 195, in start\n      self.asyncio_loop.run_forever()\n    File \"C:\\Users\\mahdi\\anaconda3\\envs\\tf\\lib\\asyncio\\windows_events.py\", line 321, in run_forever\n      super().run_forever()\n    File \"C:\\Users\\mahdi\\anaconda3\\envs\\tf\\lib\\asyncio\\base_events.py\", line 601, in run_forever\n      self._run_once()\n    File \"C:\\Users\\mahdi\\anaconda3\\envs\\tf\\lib\\asyncio\\base_events.py\", line 1905, in _run_once\n      handle._run()\n    File \"C:\\Users\\mahdi\\anaconda3\\envs\\tf\\lib\\asyncio\\events.py\", line 80, in _run\n      self._context.run(self._callback, *self._args)\n    File \"C:\\Users\\mahdi\\anaconda3\\envs\\tf\\lib\\site-packages\\ipykernel\\kernelbase.py\", line 534, in dispatch_queue\n      await self.process_one()\n    File \"C:\\Users\\mahdi\\anaconda3\\envs\\tf\\lib\\site-packages\\ipykernel\\kernelbase.py\", line 523, in process_one\n      await dispatch(*args)\n    File \"C:\\Users\\mahdi\\anaconda3\\envs\\tf\\lib\\site-packages\\ipykernel\\kernelbase.py\", line 429, in dispatch_shell\n      await result\n    File \"C:\\Users\\mahdi\\anaconda3\\envs\\tf\\lib\\site-packages\\ipykernel\\kernelbase.py\", line 767, in execute_request\n      reply_content = await reply_content\n    File \"C:\\Users\\mahdi\\anaconda3\\envs\\tf\\lib\\site-packages\\ipykernel\\ipkernel.py\", line 429, in do_execute\n      res = shell.run_cell(\n    File \"C:\\Users\\mahdi\\anaconda3\\envs\\tf\\lib\\site-packages\\ipykernel\\zmqshell.py\", line 549, in run_cell\n      return super().run_cell(*args, **kwargs)\n    File \"C:\\Users\\mahdi\\anaconda3\\envs\\tf\\lib\\site-packages\\IPython\\core\\interactiveshell.py\", line 3024, in run_cell\n      result = self._run_cell(\n    File \"C:\\Users\\mahdi\\anaconda3\\envs\\tf\\lib\\site-packages\\IPython\\core\\interactiveshell.py\", line 3079, in _run_cell\n      result = runner(coro)\n    File \"C:\\Users\\mahdi\\anaconda3\\envs\\tf\\lib\\site-packages\\IPython\\core\\async_helpers.py\", line 129, in _pseudo_sync_runner\n      coro.send(None)\n    File \"C:\\Users\\mahdi\\anaconda3\\envs\\tf\\lib\\site-packages\\IPython\\core\\interactiveshell.py\", line 3284, in run_cell_async\n      has_raised = await self.run_ast_nodes(code_ast.body, cell_name,\n    File \"C:\\Users\\mahdi\\anaconda3\\envs\\tf\\lib\\site-packages\\IPython\\core\\interactiveshell.py\", line 3466, in run_ast_nodes\n      if await self.run_code(code, result, async_=asy):\n    File \"C:\\Users\\mahdi\\anaconda3\\envs\\tf\\lib\\site-packages\\IPython\\core\\interactiveshell.py\", line 3526, in run_code\n      exec(code_obj, self.user_global_ns, self.user_ns)\n    File \"C:\\Users\\mahdi\\AppData\\Local\\Temp\\ipykernel_39624\\4024244953.py\", line 85, in <module>\n      main()\n    File \"C:\\Users\\mahdi\\AppData\\Local\\Temp\\ipykernel_39624\\4024244953.py\", line 71, in main\n      net = SegmenterNet(cfg, model_ckp_name)\n    File \"<string>\", line 40, in __init__\n    File \"<string>\", line 57, in init_network_model\n    File \"<string>\", line 127, in create_summary_ops\nNode: 'summary/saver/RestoreV2'\nDetected at node 'summary/saver/RestoreV2' defined at (most recent call last):\n    File \"C:\\Users\\mahdi\\anaconda3\\envs\\tf\\lib\\runpy.py\", line 197, in _run_module_as_main\n      return _run_code(code, main_globals, None,\n    File \"C:\\Users\\mahdi\\anaconda3\\envs\\tf\\lib\\runpy.py\", line 87, in _run_code\n      exec(code, run_globals)\n    File \"C:\\Users\\mahdi\\anaconda3\\envs\\tf\\lib\\site-packages\\ipykernel_launcher.py\", line 17, in <module>\n      app.launch_new_instance()\n    File \"C:\\Users\\mahdi\\anaconda3\\envs\\tf\\lib\\site-packages\\traitlets\\config\\application.py\", line 992, in launch_instance\n      app.start()\n    File \"C:\\Users\\mahdi\\anaconda3\\envs\\tf\\lib\\site-packages\\ipykernel\\kernelapp.py\", line 701, in start\n      self.io_loop.start()\n    File \"C:\\Users\\mahdi\\anaconda3\\envs\\tf\\lib\\site-packages\\tornado\\platform\\asyncio.py\", line 195, in start\n      self.asyncio_loop.run_forever()\n    File \"C:\\Users\\mahdi\\anaconda3\\envs\\tf\\lib\\asyncio\\windows_events.py\", line 321, in run_forever\n      super().run_forever()\n    File \"C:\\Users\\mahdi\\anaconda3\\envs\\tf\\lib\\asyncio\\base_events.py\", line 601, in run_forever\n      self._run_once()\n    File \"C:\\Users\\mahdi\\anaconda3\\envs\\tf\\lib\\asyncio\\base_events.py\", line 1905, in _run_once\n      handle._run()\n    File \"C:\\Users\\mahdi\\anaconda3\\envs\\tf\\lib\\asyncio\\events.py\", line 80, in _run\n      self._context.run(self._callback, *self._args)\n    File \"C:\\Users\\mahdi\\anaconda3\\envs\\tf\\lib\\site-packages\\ipykernel\\kernelbase.py\", line 534, in dispatch_queue\n      await self.process_one()\n    File \"C:\\Users\\mahdi\\anaconda3\\envs\\tf\\lib\\site-packages\\ipykernel\\kernelbase.py\", line 523, in process_one\n      await dispatch(*args)\n    File \"C:\\Users\\mahdi\\anaconda3\\envs\\tf\\lib\\site-packages\\ipykernel\\kernelbase.py\", line 429, in dispatch_shell\n      await result\n    File \"C:\\Users\\mahdi\\anaconda3\\envs\\tf\\lib\\site-packages\\ipykernel\\kernelbase.py\", line 767, in execute_request\n      reply_content = await reply_content\n    File \"C:\\Users\\mahdi\\anaconda3\\envs\\tf\\lib\\site-packages\\ipykernel\\ipkernel.py\", line 429, in do_execute\n      res = shell.run_cell(\n    File \"C:\\Users\\mahdi\\anaconda3\\envs\\tf\\lib\\site-packages\\ipykernel\\zmqshell.py\", line 549, in run_cell\n      return super().run_cell(*args, **kwargs)\n    File \"C:\\Users\\mahdi\\anaconda3\\envs\\tf\\lib\\site-packages\\IPython\\core\\interactiveshell.py\", line 3024, in run_cell\n      result = self._run_cell(\n    File \"C:\\Users\\mahdi\\anaconda3\\envs\\tf\\lib\\site-packages\\IPython\\core\\interactiveshell.py\", line 3079, in _run_cell\n      result = runner(coro)\n    File \"C:\\Users\\mahdi\\anaconda3\\envs\\tf\\lib\\site-packages\\IPython\\core\\async_helpers.py\", line 129, in _pseudo_sync_runner\n      coro.send(None)\n    File \"C:\\Users\\mahdi\\anaconda3\\envs\\tf\\lib\\site-packages\\IPython\\core\\interactiveshell.py\", line 3284, in run_cell_async\n      has_raised = await self.run_ast_nodes(code_ast.body, cell_name,\n    File \"C:\\Users\\mahdi\\anaconda3\\envs\\tf\\lib\\site-packages\\IPython\\core\\interactiveshell.py\", line 3466, in run_ast_nodes\n      if await self.run_code(code, result, async_=asy):\n    File \"C:\\Users\\mahdi\\anaconda3\\envs\\tf\\lib\\site-packages\\IPython\\core\\interactiveshell.py\", line 3526, in run_code\n      exec(code_obj, self.user_global_ns, self.user_ns)\n    File \"C:\\Users\\mahdi\\AppData\\Local\\Temp\\ipykernel_39624\\4024244953.py\", line 85, in <module>\n      main()\n    File \"C:\\Users\\mahdi\\AppData\\Local\\Temp\\ipykernel_39624\\4024244953.py\", line 71, in main\n      net = SegmenterNet(cfg, model_ckp_name)\n    File \"<string>\", line 40, in __init__\n    File \"<string>\", line 57, in init_network_model\n    File \"<string>\", line 127, in create_summary_ops\nNode: 'summary/saver/RestoreV2'\n2 root error(s) found.\n  (0) DATA_LOSS: Unable to open table file D:\\train_salsanet_2\\logs\\salsaNet_trained: UNKNOWN: NewRandomAccessFile failed to Create/Open: D:\\train_salsanet_2\\logs\\salsaNet_trained : Access is denied.\r\n; Input/output error\n\t [[{{node summary/saver/RestoreV2}}]]\n\t [[summary/saver/RestoreV2/_43]]\n  (1) DATA_LOSS: Unable to open table file D:\\train_salsanet_2\\logs\\salsaNet_trained: UNKNOWN: NewRandomAccessFile failed to Create/Open: D:\\train_salsanet_2\\logs\\salsaNet_trained : Access is denied.\r\n; Input/output error\n\t [[{{node summary/saver/RestoreV2}}]]\n0 successful operations.\n0 derived errors ignored.\n\nOriginal stack trace for 'summary/saver/RestoreV2':\n  File \"C:\\Users\\mahdi\\anaconda3\\envs\\tf\\lib\\runpy.py\", line 197, in _run_module_as_main\n    return _run_code(code, main_globals, None,\n  File \"C:\\Users\\mahdi\\anaconda3\\envs\\tf\\lib\\runpy.py\", line 87, in _run_code\n    exec(code, run_globals)\n  File \"C:\\Users\\mahdi\\anaconda3\\envs\\tf\\lib\\site-packages\\ipykernel_launcher.py\", line 17, in <module>\n    app.launch_new_instance()\n  File \"C:\\Users\\mahdi\\anaconda3\\envs\\tf\\lib\\site-packages\\traitlets\\config\\application.py\", line 992, in launch_instance\n    app.start()\n  File \"C:\\Users\\mahdi\\anaconda3\\envs\\tf\\lib\\site-packages\\ipykernel\\kernelapp.py\", line 701, in start\n    self.io_loop.start()\n  File \"C:\\Users\\mahdi\\anaconda3\\envs\\tf\\lib\\site-packages\\tornado\\platform\\asyncio.py\", line 195, in start\n    self.asyncio_loop.run_forever()\n  File \"C:\\Users\\mahdi\\anaconda3\\envs\\tf\\lib\\asyncio\\windows_events.py\", line 321, in run_forever\n    super().run_forever()\n  File \"C:\\Users\\mahdi\\anaconda3\\envs\\tf\\lib\\asyncio\\base_events.py\", line 601, in run_forever\n    self._run_once()\n  File \"C:\\Users\\mahdi\\anaconda3\\envs\\tf\\lib\\asyncio\\base_events.py\", line 1905, in _run_once\n    handle._run()\n  File \"C:\\Users\\mahdi\\anaconda3\\envs\\tf\\lib\\asyncio\\events.py\", line 80, in _run\n    self._context.run(self._callback, *self._args)\n  File \"C:\\Users\\mahdi\\anaconda3\\envs\\tf\\lib\\site-packages\\ipykernel\\kernelbase.py\", line 534, in dispatch_queue\n    await self.process_one()\n  File \"C:\\Users\\mahdi\\anaconda3\\envs\\tf\\lib\\site-packages\\ipykernel\\kernelbase.py\", line 523, in process_one\n    await dispatch(*args)\n  File \"C:\\Users\\mahdi\\anaconda3\\envs\\tf\\lib\\site-packages\\ipykernel\\kernelbase.py\", line 429, in dispatch_shell\n    await result\n  File \"C:\\Users\\mahdi\\anaconda3\\envs\\tf\\lib\\site-packages\\ipykernel\\kernelbase.py\", line 767, in execute_request\n    reply_content = await reply_content\n  File \"C:\\Users\\mahdi\\anaconda3\\envs\\tf\\lib\\site-packages\\ipykernel\\ipkernel.py\", line 429, in do_execute\n    res = shell.run_cell(\n  File \"C:\\Users\\mahdi\\anaconda3\\envs\\tf\\lib\\site-packages\\ipykernel\\zmqshell.py\", line 549, in run_cell\n    return super().run_cell(*args, **kwargs)\n  File \"C:\\Users\\mahdi\\anaconda3\\envs\\tf\\lib\\site-packages\\IPython\\core\\interactiveshell.py\", line 3024, in run_cell\n    result = self._run_cell(\n  File \"C:\\Users\\mahdi\\anaconda3\\envs\\tf\\lib\\site-packages\\IPython\\core\\interactiveshell.py\", line 3079, in _run_cell\n    result = runner(coro)\n  File \"C:\\Users\\mahdi\\anaconda3\\envs\\tf\\lib\\site-packages\\IPython\\core\\async_helpers.py\", line 129, in _pseudo_sync_runner\n    coro.send(None)\n  File \"C:\\Users\\mahdi\\anaconda3\\envs\\tf\\lib\\site-packages\\IPython\\core\\interactiveshell.py\", line 3284, in run_cell_async\n    has_raised = await self.run_ast_nodes(code_ast.body, cell_name,\n  File \"C:\\Users\\mahdi\\anaconda3\\envs\\tf\\lib\\site-packages\\IPython\\core\\interactiveshell.py\", line 3466, in run_ast_nodes\n    if await self.run_code(code, result, async_=asy):\n  File \"C:\\Users\\mahdi\\anaconda3\\envs\\tf\\lib\\site-packages\\IPython\\core\\interactiveshell.py\", line 3526, in run_code\n    exec(code_obj, self.user_global_ns, self.user_ns)\n  File \"C:\\Users\\mahdi\\AppData\\Local\\Temp\\ipykernel_39624\\4024244953.py\", line 85, in <module>\n    main()\n  File \"C:\\Users\\mahdi\\AppData\\Local\\Temp\\ipykernel_39624\\4024244953.py\", line 71, in main\n    net = SegmenterNet(cfg, model_ckp_name)\n  File \"<string>\", line 40, in __init__\n  File \"<string>\", line 57, in init_network_model\n  File \"<string>\", line 127, in create_summary_ops\n  File \"C:\\Users\\mahdi\\anaconda3\\envs\\tf\\lib\\site-packages\\tensorflow\\python\\training\\saver.py\", line 931, in __init__\n    self.build()\n  File \"C:\\Users\\mahdi\\anaconda3\\envs\\tf\\lib\\site-packages\\tensorflow\\python\\training\\saver.py\", line 943, in build\n    self._build(self._filename, build_save=True, build_restore=True)\n  File \"C:\\Users\\mahdi\\anaconda3\\envs\\tf\\lib\\site-packages\\tensorflow\\python\\training\\saver.py\", line 971, in _build\n    self.saver_def = self._builder._build_internal(  # pylint: disable=protected-access\n  File \"C:\\Users\\mahdi\\anaconda3\\envs\\tf\\lib\\site-packages\\tensorflow\\python\\training\\saver.py\", line 540, in _build_internal\n    restore_op = self._AddRestoreOps(filename_tensor, saveables,\n  File \"C:\\Users\\mahdi\\anaconda3\\envs\\tf\\lib\\site-packages\\tensorflow\\python\\training\\saver.py\", line 360, in _AddRestoreOps\n    all_tensors = self.bulk_restore(filename_tensor, saveables, preferred_shard,\n  File \"C:\\Users\\mahdi\\anaconda3\\envs\\tf\\lib\\site-packages\\tensorflow\\python\\training\\saver.py\", line 608, in bulk_restore\n    return io_ops.restore_v2(filename_tensor, names, slices, dtypes)\n  File \"C:\\Users\\mahdi\\anaconda3\\envs\\tf\\lib\\site-packages\\tensorflow\\python\\ops\\gen_io_ops.py\", line 1516, in restore_v2\n    _, _, _op, _outputs = _op_def_library._apply_op_helper(\n  File \"C:\\Users\\mahdi\\anaconda3\\envs\\tf\\lib\\site-packages\\tensorflow\\python\\framework\\op_def_library.py\", line 797, in _apply_op_helper\n    op = g._create_op_internal(op_type_name, inputs, dtypes=None,\n  File \"C:\\Users\\mahdi\\anaconda3\\envs\\tf\\lib\\site-packages\\tensorflow\\python\\framework\\ops.py\", line 3800, in _create_op_internal\n    ret = Operation(\n",
     "output_type": "error",
     "traceback": [
      "\u001b[1;31m---------------------------------------------------------------------------\u001b[0m",
      "\u001b[1;31mDataLossError\u001b[0m                             Traceback (most recent call last)",
      "File \u001b[1;32m~\\anaconda3\\envs\\tf\\lib\\site-packages\\tensorflow\\python\\client\\session.py:1378\u001b[0m, in \u001b[0;36mBaseSession._do_call\u001b[1;34m(self, fn, *args)\u001b[0m\n\u001b[0;32m   1377\u001b[0m \u001b[38;5;28;01mtry\u001b[39;00m:\n\u001b[1;32m-> 1378\u001b[0m   \u001b[38;5;28;01mreturn\u001b[39;00m \u001b[43mfn\u001b[49m\u001b[43m(\u001b[49m\u001b[38;5;241;43m*\u001b[39;49m\u001b[43margs\u001b[49m\u001b[43m)\u001b[49m\n\u001b[0;32m   1379\u001b[0m \u001b[38;5;28;01mexcept\u001b[39;00m errors\u001b[38;5;241m.\u001b[39mOpError \u001b[38;5;28;01mas\u001b[39;00m e:\n",
      "File \u001b[1;32m~\\anaconda3\\envs\\tf\\lib\\site-packages\\tensorflow\\python\\client\\session.py:1361\u001b[0m, in \u001b[0;36mBaseSession._do_run.<locals>._run_fn\u001b[1;34m(feed_dict, fetch_list, target_list, options, run_metadata)\u001b[0m\n\u001b[0;32m   1360\u001b[0m \u001b[38;5;28mself\u001b[39m\u001b[38;5;241m.\u001b[39m_extend_graph()\n\u001b[1;32m-> 1361\u001b[0m \u001b[38;5;28;01mreturn\u001b[39;00m \u001b[38;5;28;43mself\u001b[39;49m\u001b[38;5;241;43m.\u001b[39;49m\u001b[43m_call_tf_sessionrun\u001b[49m\u001b[43m(\u001b[49m\u001b[43moptions\u001b[49m\u001b[43m,\u001b[49m\u001b[43m \u001b[49m\u001b[43mfeed_dict\u001b[49m\u001b[43m,\u001b[49m\u001b[43m \u001b[49m\u001b[43mfetch_list\u001b[49m\u001b[43m,\u001b[49m\n\u001b[0;32m   1362\u001b[0m \u001b[43m                                \u001b[49m\u001b[43mtarget_list\u001b[49m\u001b[43m,\u001b[49m\u001b[43m \u001b[49m\u001b[43mrun_metadata\u001b[49m\u001b[43m)\u001b[49m\n",
      "File \u001b[1;32m~\\anaconda3\\envs\\tf\\lib\\site-packages\\tensorflow\\python\\client\\session.py:1454\u001b[0m, in \u001b[0;36mBaseSession._call_tf_sessionrun\u001b[1;34m(self, options, feed_dict, fetch_list, target_list, run_metadata)\u001b[0m\n\u001b[0;32m   1452\u001b[0m \u001b[38;5;28;01mdef\u001b[39;00m \u001b[38;5;21m_call_tf_sessionrun\u001b[39m(\u001b[38;5;28mself\u001b[39m, options, feed_dict, fetch_list, target_list,\n\u001b[0;32m   1453\u001b[0m                         run_metadata):\n\u001b[1;32m-> 1454\u001b[0m   \u001b[38;5;28;01mreturn\u001b[39;00m \u001b[43mtf_session\u001b[49m\u001b[38;5;241;43m.\u001b[39;49m\u001b[43mTF_SessionRun_wrapper\u001b[49m\u001b[43m(\u001b[49m\u001b[38;5;28;43mself\u001b[39;49m\u001b[38;5;241;43m.\u001b[39;49m\u001b[43m_session\u001b[49m\u001b[43m,\u001b[49m\u001b[43m \u001b[49m\u001b[43moptions\u001b[49m\u001b[43m,\u001b[49m\u001b[43m \u001b[49m\u001b[43mfeed_dict\u001b[49m\u001b[43m,\u001b[49m\n\u001b[0;32m   1455\u001b[0m \u001b[43m                                          \u001b[49m\u001b[43mfetch_list\u001b[49m\u001b[43m,\u001b[49m\u001b[43m \u001b[49m\u001b[43mtarget_list\u001b[49m\u001b[43m,\u001b[49m\n\u001b[0;32m   1456\u001b[0m \u001b[43m                                          \u001b[49m\u001b[43mrun_metadata\u001b[49m\u001b[43m)\u001b[49m\n",
      "\u001b[1;31mDataLossError\u001b[0m: 2 root error(s) found.\n  (0) DATA_LOSS: Unable to open table file D:\\train_salsanet_2\\logs\\salsaNet_trained: UNKNOWN: NewRandomAccessFile failed to Create/Open: D:\\train_salsanet_2\\logs\\salsaNet_trained : Access is denied.\r\n; Input/output error\n\t [[{{node summary/saver/RestoreV2}}]]\n\t [[summary/saver/RestoreV2/_43]]\n  (1) DATA_LOSS: Unable to open table file D:\\train_salsanet_2\\logs\\salsaNet_trained: UNKNOWN: NewRandomAccessFile failed to Create/Open: D:\\train_salsanet_2\\logs\\salsaNet_trained : Access is denied.\r\n; Input/output error\n\t [[{{node summary/saver/RestoreV2}}]]\n0 successful operations.\n0 derived errors ignored.",
      "\nDuring handling of the above exception, another exception occurred:\n",
      "\u001b[1;31mDataLossError\u001b[0m                             Traceback (most recent call last)",
      "Cell \u001b[1;32mIn[7], line 85\u001b[0m\n\u001b[0;32m     81\u001b[0m     \u001b[38;5;28;01mreturn\u001b[39;00m\n\u001b[0;32m     83\u001b[0m \u001b[38;5;28;01mif\u001b[39;00m \u001b[38;5;18m__name__\u001b[39m \u001b[38;5;241m==\u001b[39m \u001b[38;5;124m'\u001b[39m\u001b[38;5;124m__main__\u001b[39m\u001b[38;5;124m'\u001b[39m:\n\u001b[1;32m---> 85\u001b[0m     \u001b[43mmain\u001b[49m\u001b[43m(\u001b[49m\u001b[43m)\u001b[49m\n",
      "Cell \u001b[1;32mIn[7], line 75\u001b[0m, in \u001b[0;36mmain\u001b[1;34m()\u001b[0m\n\u001b[0;32m     73\u001b[0m \u001b[38;5;66;03m# testing with the already created bird eye view images\u001b[39;00m\n\u001b[0;32m     74\u001b[0m test_bev_img \u001b[38;5;241m=\u001b[39m \u001b[38;5;124m\"\u001b[39m\u001b[38;5;124mC:/Users/mahdi/Downloads/test_bev_image.npy\u001b[39m\u001b[38;5;124m\"\u001b[39m\n\u001b[1;32m---> 75\u001b[0m test_with_bev_images(net, test_bev_img)\n\u001b[0;32m     77\u001b[0m \u001b[38;5;66;03m# testing by using the raw point cloud data\u001b[39;00m\n\u001b[0;32m     78\u001b[0m \u001b[38;5;66;03m#test_cloud = \"../data/test_cloud.npy\"\u001b[39;00m\n\u001b[0;32m     79\u001b[0m \u001b[38;5;66;03m#test_with_point_cloud(net, cfg, test_cloud)\u001b[39;00m\n\u001b[0;32m     81\u001b[0m \u001b[38;5;28;01mreturn\u001b[39;00m\n",
      "Cell \u001b[1;32mIn[7], line 18\u001b[0m, in \u001b[0;36mtest_with_bev_images\u001b[1;34m(net, img)\u001b[0m\n\u001b[0;32m     15\u001b[0m \u001b[38;5;28;01mdef\u001b[39;00m \u001b[38;5;21mtest_with_bev_images\u001b[39m (net, img):\n\u001b[0;32m     17\u001b[0m     \u001b[38;5;28;01mwith\u001b[39;00m tf\u001b[38;5;241m.\u001b[39mcompat\u001b[38;5;241m.\u001b[39mv1\u001b[38;5;241m.\u001b[39mSession(graph\u001b[38;5;241m=\u001b[39mnet\u001b[38;5;241m.\u001b[39mgraph) \u001b[38;5;28;01mas\u001b[39;00m sess:\n\u001b[1;32m---> 18\u001b[0m         net\u001b[38;5;241m.\u001b[39minitialize_vars(sess)\n\u001b[0;32m     20\u001b[0m         \u001b[38;5;28mprint\u001b[39m(\u001b[38;5;124m\"\u001b[39m\u001b[38;5;124mloading bev img \u001b[39m\u001b[38;5;124m\"\u001b[39m \u001b[38;5;241m+\u001b[39m \u001b[38;5;28mstr\u001b[39m(img))\n\u001b[0;32m     21\u001b[0m         lidar_data \u001b[38;5;241m=\u001b[39m np\u001b[38;5;241m.\u001b[39mload(img)\n",
      "File \u001b[1;32m<string>:191\u001b[0m, in \u001b[0;36minitialize_vars\u001b[1;34m(self, session)\u001b[0m\n",
      "File \u001b[1;32m~\\anaconda3\\envs\\tf\\lib\\site-packages\\tensorflow\\python\\training\\saver.py:1415\u001b[0m, in \u001b[0;36mSaver.restore\u001b[1;34m(self, sess, save_path)\u001b[0m\n\u001b[0;32m   1413\u001b[0m     \u001b[38;5;28mself\u001b[39m\u001b[38;5;241m.\u001b[39m_build_eager(save_path, build_save\u001b[38;5;241m=\u001b[39m\u001b[38;5;28;01mFalse\u001b[39;00m, build_restore\u001b[38;5;241m=\u001b[39m\u001b[38;5;28;01mTrue\u001b[39;00m)\n\u001b[0;32m   1414\u001b[0m   \u001b[38;5;28;01melse\u001b[39;00m:\n\u001b[1;32m-> 1415\u001b[0m     \u001b[43msess\u001b[49m\u001b[38;5;241;43m.\u001b[39;49m\u001b[43mrun\u001b[49m\u001b[43m(\u001b[49m\u001b[38;5;28;43mself\u001b[39;49m\u001b[38;5;241;43m.\u001b[39;49m\u001b[43msaver_def\u001b[49m\u001b[38;5;241;43m.\u001b[39;49m\u001b[43mrestore_op_name\u001b[49m\u001b[43m,\u001b[49m\n\u001b[0;32m   1416\u001b[0m \u001b[43m             \u001b[49m\u001b[43m{\u001b[49m\u001b[38;5;28;43mself\u001b[39;49m\u001b[38;5;241;43m.\u001b[39;49m\u001b[43msaver_def\u001b[49m\u001b[38;5;241;43m.\u001b[39;49m\u001b[43mfilename_tensor_name\u001b[49m\u001b[43m:\u001b[49m\u001b[43m \u001b[49m\u001b[43msave_path\u001b[49m\u001b[43m}\u001b[49m\u001b[43m)\u001b[49m\n\u001b[0;32m   1417\u001b[0m \u001b[38;5;28;01mexcept\u001b[39;00m errors\u001b[38;5;241m.\u001b[39mNotFoundError \u001b[38;5;28;01mas\u001b[39;00m err:\n\u001b[0;32m   1418\u001b[0m   \u001b[38;5;66;03m# There are three common conditions that might cause this error:\u001b[39;00m\n\u001b[0;32m   1419\u001b[0m   \u001b[38;5;66;03m# 0. The file is missing. We ignore here, as this is checked above.\u001b[39;00m\n\u001b[1;32m   (...)\u001b[0m\n\u001b[0;32m   1423\u001b[0m   \u001b[38;5;66;03m# 1. The checkpoint would not be loaded successfully as is. Try to parse\u001b[39;00m\n\u001b[0;32m   1424\u001b[0m   \u001b[38;5;66;03m# it as an object-based checkpoint.\u001b[39;00m\n\u001b[0;32m   1425\u001b[0m   \u001b[38;5;28;01mtry\u001b[39;00m:\n",
      "File \u001b[1;32m~\\anaconda3\\envs\\tf\\lib\\site-packages\\tensorflow\\python\\client\\session.py:968\u001b[0m, in \u001b[0;36mBaseSession.run\u001b[1;34m(self, fetches, feed_dict, options, run_metadata)\u001b[0m\n\u001b[0;32m    965\u001b[0m run_metadata_ptr \u001b[38;5;241m=\u001b[39m tf_session\u001b[38;5;241m.\u001b[39mTF_NewBuffer() \u001b[38;5;28;01mif\u001b[39;00m run_metadata \u001b[38;5;28;01melse\u001b[39;00m \u001b[38;5;28;01mNone\u001b[39;00m\n\u001b[0;32m    967\u001b[0m \u001b[38;5;28;01mtry\u001b[39;00m:\n\u001b[1;32m--> 968\u001b[0m   result \u001b[38;5;241m=\u001b[39m \u001b[38;5;28;43mself\u001b[39;49m\u001b[38;5;241;43m.\u001b[39;49m\u001b[43m_run\u001b[49m\u001b[43m(\u001b[49m\u001b[38;5;28;43;01mNone\u001b[39;49;00m\u001b[43m,\u001b[49m\u001b[43m \u001b[49m\u001b[43mfetches\u001b[49m\u001b[43m,\u001b[49m\u001b[43m \u001b[49m\u001b[43mfeed_dict\u001b[49m\u001b[43m,\u001b[49m\u001b[43m \u001b[49m\u001b[43moptions_ptr\u001b[49m\u001b[43m,\u001b[49m\n\u001b[0;32m    969\u001b[0m \u001b[43m                     \u001b[49m\u001b[43mrun_metadata_ptr\u001b[49m\u001b[43m)\u001b[49m\n\u001b[0;32m    970\u001b[0m   \u001b[38;5;28;01mif\u001b[39;00m run_metadata:\n\u001b[0;32m    971\u001b[0m     proto_data \u001b[38;5;241m=\u001b[39m tf_session\u001b[38;5;241m.\u001b[39mTF_GetBuffer(run_metadata_ptr)\n",
      "File \u001b[1;32m~\\anaconda3\\envs\\tf\\lib\\site-packages\\tensorflow\\python\\client\\session.py:1191\u001b[0m, in \u001b[0;36mBaseSession._run\u001b[1;34m(self, handle, fetches, feed_dict, options, run_metadata)\u001b[0m\n\u001b[0;32m   1188\u001b[0m \u001b[38;5;66;03m# We only want to really perform the run if fetches or targets are provided,\u001b[39;00m\n\u001b[0;32m   1189\u001b[0m \u001b[38;5;66;03m# or if the call is a partial run that specifies feeds.\u001b[39;00m\n\u001b[0;32m   1190\u001b[0m \u001b[38;5;28;01mif\u001b[39;00m final_fetches \u001b[38;5;129;01mor\u001b[39;00m final_targets \u001b[38;5;129;01mor\u001b[39;00m (handle \u001b[38;5;129;01mand\u001b[39;00m feed_dict_tensor):\n\u001b[1;32m-> 1191\u001b[0m   results \u001b[38;5;241m=\u001b[39m \u001b[38;5;28;43mself\u001b[39;49m\u001b[38;5;241;43m.\u001b[39;49m\u001b[43m_do_run\u001b[49m\u001b[43m(\u001b[49m\u001b[43mhandle\u001b[49m\u001b[43m,\u001b[49m\u001b[43m \u001b[49m\u001b[43mfinal_targets\u001b[49m\u001b[43m,\u001b[49m\u001b[43m \u001b[49m\u001b[43mfinal_fetches\u001b[49m\u001b[43m,\u001b[49m\n\u001b[0;32m   1192\u001b[0m \u001b[43m                         \u001b[49m\u001b[43mfeed_dict_tensor\u001b[49m\u001b[43m,\u001b[49m\u001b[43m \u001b[49m\u001b[43moptions\u001b[49m\u001b[43m,\u001b[49m\u001b[43m \u001b[49m\u001b[43mrun_metadata\u001b[49m\u001b[43m)\u001b[49m\n\u001b[0;32m   1193\u001b[0m \u001b[38;5;28;01melse\u001b[39;00m:\n\u001b[0;32m   1194\u001b[0m   results \u001b[38;5;241m=\u001b[39m []\n",
      "File \u001b[1;32m~\\anaconda3\\envs\\tf\\lib\\site-packages\\tensorflow\\python\\client\\session.py:1371\u001b[0m, in \u001b[0;36mBaseSession._do_run\u001b[1;34m(self, handle, target_list, fetch_list, feed_dict, options, run_metadata)\u001b[0m\n\u001b[0;32m   1368\u001b[0m   \u001b[38;5;28;01mreturn\u001b[39;00m \u001b[38;5;28mself\u001b[39m\u001b[38;5;241m.\u001b[39m_call_tf_sessionprun(handle, feed_dict, fetch_list)\n\u001b[0;32m   1370\u001b[0m \u001b[38;5;28;01mif\u001b[39;00m handle \u001b[38;5;129;01mis\u001b[39;00m \u001b[38;5;28;01mNone\u001b[39;00m:\n\u001b[1;32m-> 1371\u001b[0m   \u001b[38;5;28;01mreturn\u001b[39;00m \u001b[38;5;28;43mself\u001b[39;49m\u001b[38;5;241;43m.\u001b[39;49m\u001b[43m_do_call\u001b[49m\u001b[43m(\u001b[49m\u001b[43m_run_fn\u001b[49m\u001b[43m,\u001b[49m\u001b[43m \u001b[49m\u001b[43mfeeds\u001b[49m\u001b[43m,\u001b[49m\u001b[43m \u001b[49m\u001b[43mfetches\u001b[49m\u001b[43m,\u001b[49m\u001b[43m \u001b[49m\u001b[43mtargets\u001b[49m\u001b[43m,\u001b[49m\u001b[43m \u001b[49m\u001b[43moptions\u001b[49m\u001b[43m,\u001b[49m\n\u001b[0;32m   1372\u001b[0m \u001b[43m                       \u001b[49m\u001b[43mrun_metadata\u001b[49m\u001b[43m)\u001b[49m\n\u001b[0;32m   1373\u001b[0m \u001b[38;5;28;01melse\u001b[39;00m:\n\u001b[0;32m   1374\u001b[0m   \u001b[38;5;28;01mreturn\u001b[39;00m \u001b[38;5;28mself\u001b[39m\u001b[38;5;241m.\u001b[39m_do_call(_prun_fn, handle, feeds, fetches)\n",
      "File \u001b[1;32m~\\anaconda3\\envs\\tf\\lib\\site-packages\\tensorflow\\python\\client\\session.py:1397\u001b[0m, in \u001b[0;36mBaseSession._do_call\u001b[1;34m(self, fn, *args)\u001b[0m\n\u001b[0;32m   1392\u001b[0m \u001b[38;5;28;01mif\u001b[39;00m \u001b[38;5;124m'\u001b[39m\u001b[38;5;124monly supports NHWC tensor format\u001b[39m\u001b[38;5;124m'\u001b[39m \u001b[38;5;129;01min\u001b[39;00m message:\n\u001b[0;32m   1393\u001b[0m   message \u001b[38;5;241m+\u001b[39m\u001b[38;5;241m=\u001b[39m (\u001b[38;5;124m'\u001b[39m\u001b[38;5;130;01m\\n\u001b[39;00m\u001b[38;5;124mA possible workaround: Try disabling Grappler optimizer\u001b[39m\u001b[38;5;124m'\u001b[39m\n\u001b[0;32m   1394\u001b[0m               \u001b[38;5;124m'\u001b[39m\u001b[38;5;130;01m\\n\u001b[39;00m\u001b[38;5;124mby modifying the config for creating the session eg.\u001b[39m\u001b[38;5;124m'\u001b[39m\n\u001b[0;32m   1395\u001b[0m               \u001b[38;5;124m'\u001b[39m\u001b[38;5;130;01m\\n\u001b[39;00m\u001b[38;5;124msession_config.graph_options.rewrite_options.\u001b[39m\u001b[38;5;124m'\u001b[39m\n\u001b[0;32m   1396\u001b[0m               \u001b[38;5;124m'\u001b[39m\u001b[38;5;124mdisable_meta_optimizer = True\u001b[39m\u001b[38;5;124m'\u001b[39m)\n\u001b[1;32m-> 1397\u001b[0m \u001b[38;5;28;01mraise\u001b[39;00m \u001b[38;5;28mtype\u001b[39m(e)(node_def, op, message)\n",
      "\u001b[1;31mDataLossError\u001b[0m: Graph execution error:\n\nDetected at node 'summary/saver/RestoreV2' defined at (most recent call last):\n    File \"C:\\Users\\mahdi\\anaconda3\\envs\\tf\\lib\\runpy.py\", line 197, in _run_module_as_main\n      return _run_code(code, main_globals, None,\n    File \"C:\\Users\\mahdi\\anaconda3\\envs\\tf\\lib\\runpy.py\", line 87, in _run_code\n      exec(code, run_globals)\n    File \"C:\\Users\\mahdi\\anaconda3\\envs\\tf\\lib\\site-packages\\ipykernel_launcher.py\", line 17, in <module>\n      app.launch_new_instance()\n    File \"C:\\Users\\mahdi\\anaconda3\\envs\\tf\\lib\\site-packages\\traitlets\\config\\application.py\", line 992, in launch_instance\n      app.start()\n    File \"C:\\Users\\mahdi\\anaconda3\\envs\\tf\\lib\\site-packages\\ipykernel\\kernelapp.py\", line 701, in start\n      self.io_loop.start()\n    File \"C:\\Users\\mahdi\\anaconda3\\envs\\tf\\lib\\site-packages\\tornado\\platform\\asyncio.py\", line 195, in start\n      self.asyncio_loop.run_forever()\n    File \"C:\\Users\\mahdi\\anaconda3\\envs\\tf\\lib\\asyncio\\windows_events.py\", line 321, in run_forever\n      super().run_forever()\n    File \"C:\\Users\\mahdi\\anaconda3\\envs\\tf\\lib\\asyncio\\base_events.py\", line 601, in run_forever\n      self._run_once()\n    File \"C:\\Users\\mahdi\\anaconda3\\envs\\tf\\lib\\asyncio\\base_events.py\", line 1905, in _run_once\n      handle._run()\n    File \"C:\\Users\\mahdi\\anaconda3\\envs\\tf\\lib\\asyncio\\events.py\", line 80, in _run\n      self._context.run(self._callback, *self._args)\n    File \"C:\\Users\\mahdi\\anaconda3\\envs\\tf\\lib\\site-packages\\ipykernel\\kernelbase.py\", line 534, in dispatch_queue\n      await self.process_one()\n    File \"C:\\Users\\mahdi\\anaconda3\\envs\\tf\\lib\\site-packages\\ipykernel\\kernelbase.py\", line 523, in process_one\n      await dispatch(*args)\n    File \"C:\\Users\\mahdi\\anaconda3\\envs\\tf\\lib\\site-packages\\ipykernel\\kernelbase.py\", line 429, in dispatch_shell\n      await result\n    File \"C:\\Users\\mahdi\\anaconda3\\envs\\tf\\lib\\site-packages\\ipykernel\\kernelbase.py\", line 767, in execute_request\n      reply_content = await reply_content\n    File \"C:\\Users\\mahdi\\anaconda3\\envs\\tf\\lib\\site-packages\\ipykernel\\ipkernel.py\", line 429, in do_execute\n      res = shell.run_cell(\n    File \"C:\\Users\\mahdi\\anaconda3\\envs\\tf\\lib\\site-packages\\ipykernel\\zmqshell.py\", line 549, in run_cell\n      return super().run_cell(*args, **kwargs)\n    File \"C:\\Users\\mahdi\\anaconda3\\envs\\tf\\lib\\site-packages\\IPython\\core\\interactiveshell.py\", line 3024, in run_cell\n      result = self._run_cell(\n    File \"C:\\Users\\mahdi\\anaconda3\\envs\\tf\\lib\\site-packages\\IPython\\core\\interactiveshell.py\", line 3079, in _run_cell\n      result = runner(coro)\n    File \"C:\\Users\\mahdi\\anaconda3\\envs\\tf\\lib\\site-packages\\IPython\\core\\async_helpers.py\", line 129, in _pseudo_sync_runner\n      coro.send(None)\n    File \"C:\\Users\\mahdi\\anaconda3\\envs\\tf\\lib\\site-packages\\IPython\\core\\interactiveshell.py\", line 3284, in run_cell_async\n      has_raised = await self.run_ast_nodes(code_ast.body, cell_name,\n    File \"C:\\Users\\mahdi\\anaconda3\\envs\\tf\\lib\\site-packages\\IPython\\core\\interactiveshell.py\", line 3466, in run_ast_nodes\n      if await self.run_code(code, result, async_=asy):\n    File \"C:\\Users\\mahdi\\anaconda3\\envs\\tf\\lib\\site-packages\\IPython\\core\\interactiveshell.py\", line 3526, in run_code\n      exec(code_obj, self.user_global_ns, self.user_ns)\n    File \"C:\\Users\\mahdi\\AppData\\Local\\Temp\\ipykernel_39624\\4024244953.py\", line 85, in <module>\n      main()\n    File \"C:\\Users\\mahdi\\AppData\\Local\\Temp\\ipykernel_39624\\4024244953.py\", line 71, in main\n      net = SegmenterNet(cfg, model_ckp_name)\n    File \"<string>\", line 40, in __init__\n    File \"<string>\", line 57, in init_network_model\n    File \"<string>\", line 127, in create_summary_ops\nNode: 'summary/saver/RestoreV2'\nDetected at node 'summary/saver/RestoreV2' defined at (most recent call last):\n    File \"C:\\Users\\mahdi\\anaconda3\\envs\\tf\\lib\\runpy.py\", line 197, in _run_module_as_main\n      return _run_code(code, main_globals, None,\n    File \"C:\\Users\\mahdi\\anaconda3\\envs\\tf\\lib\\runpy.py\", line 87, in _run_code\n      exec(code, run_globals)\n    File \"C:\\Users\\mahdi\\anaconda3\\envs\\tf\\lib\\site-packages\\ipykernel_launcher.py\", line 17, in <module>\n      app.launch_new_instance()\n    File \"C:\\Users\\mahdi\\anaconda3\\envs\\tf\\lib\\site-packages\\traitlets\\config\\application.py\", line 992, in launch_instance\n      app.start()\n    File \"C:\\Users\\mahdi\\anaconda3\\envs\\tf\\lib\\site-packages\\ipykernel\\kernelapp.py\", line 701, in start\n      self.io_loop.start()\n    File \"C:\\Users\\mahdi\\anaconda3\\envs\\tf\\lib\\site-packages\\tornado\\platform\\asyncio.py\", line 195, in start\n      self.asyncio_loop.run_forever()\n    File \"C:\\Users\\mahdi\\anaconda3\\envs\\tf\\lib\\asyncio\\windows_events.py\", line 321, in run_forever\n      super().run_forever()\n    File \"C:\\Users\\mahdi\\anaconda3\\envs\\tf\\lib\\asyncio\\base_events.py\", line 601, in run_forever\n      self._run_once()\n    File \"C:\\Users\\mahdi\\anaconda3\\envs\\tf\\lib\\asyncio\\base_events.py\", line 1905, in _run_once\n      handle._run()\n    File \"C:\\Users\\mahdi\\anaconda3\\envs\\tf\\lib\\asyncio\\events.py\", line 80, in _run\n      self._context.run(self._callback, *self._args)\n    File \"C:\\Users\\mahdi\\anaconda3\\envs\\tf\\lib\\site-packages\\ipykernel\\kernelbase.py\", line 534, in dispatch_queue\n      await self.process_one()\n    File \"C:\\Users\\mahdi\\anaconda3\\envs\\tf\\lib\\site-packages\\ipykernel\\kernelbase.py\", line 523, in process_one\n      await dispatch(*args)\n    File \"C:\\Users\\mahdi\\anaconda3\\envs\\tf\\lib\\site-packages\\ipykernel\\kernelbase.py\", line 429, in dispatch_shell\n      await result\n    File \"C:\\Users\\mahdi\\anaconda3\\envs\\tf\\lib\\site-packages\\ipykernel\\kernelbase.py\", line 767, in execute_request\n      reply_content = await reply_content\n    File \"C:\\Users\\mahdi\\anaconda3\\envs\\tf\\lib\\site-packages\\ipykernel\\ipkernel.py\", line 429, in do_execute\n      res = shell.run_cell(\n    File \"C:\\Users\\mahdi\\anaconda3\\envs\\tf\\lib\\site-packages\\ipykernel\\zmqshell.py\", line 549, in run_cell\n      return super().run_cell(*args, **kwargs)\n    File \"C:\\Users\\mahdi\\anaconda3\\envs\\tf\\lib\\site-packages\\IPython\\core\\interactiveshell.py\", line 3024, in run_cell\n      result = self._run_cell(\n    File \"C:\\Users\\mahdi\\anaconda3\\envs\\tf\\lib\\site-packages\\IPython\\core\\interactiveshell.py\", line 3079, in _run_cell\n      result = runner(coro)\n    File \"C:\\Users\\mahdi\\anaconda3\\envs\\tf\\lib\\site-packages\\IPython\\core\\async_helpers.py\", line 129, in _pseudo_sync_runner\n      coro.send(None)\n    File \"C:\\Users\\mahdi\\anaconda3\\envs\\tf\\lib\\site-packages\\IPython\\core\\interactiveshell.py\", line 3284, in run_cell_async\n      has_raised = await self.run_ast_nodes(code_ast.body, cell_name,\n    File \"C:\\Users\\mahdi\\anaconda3\\envs\\tf\\lib\\site-packages\\IPython\\core\\interactiveshell.py\", line 3466, in run_ast_nodes\n      if await self.run_code(code, result, async_=asy):\n    File \"C:\\Users\\mahdi\\anaconda3\\envs\\tf\\lib\\site-packages\\IPython\\core\\interactiveshell.py\", line 3526, in run_code\n      exec(code_obj, self.user_global_ns, self.user_ns)\n    File \"C:\\Users\\mahdi\\AppData\\Local\\Temp\\ipykernel_39624\\4024244953.py\", line 85, in <module>\n      main()\n    File \"C:\\Users\\mahdi\\AppData\\Local\\Temp\\ipykernel_39624\\4024244953.py\", line 71, in main\n      net = SegmenterNet(cfg, model_ckp_name)\n    File \"<string>\", line 40, in __init__\n    File \"<string>\", line 57, in init_network_model\n    File \"<string>\", line 127, in create_summary_ops\nNode: 'summary/saver/RestoreV2'\n2 root error(s) found.\n  (0) DATA_LOSS: Unable to open table file D:\\train_salsanet_2\\logs\\salsaNet_trained: UNKNOWN: NewRandomAccessFile failed to Create/Open: D:\\train_salsanet_2\\logs\\salsaNet_trained : Access is denied.\r\n; Input/output error\n\t [[{{node summary/saver/RestoreV2}}]]\n\t [[summary/saver/RestoreV2/_43]]\n  (1) DATA_LOSS: Unable to open table file D:\\train_salsanet_2\\logs\\salsaNet_trained: UNKNOWN: NewRandomAccessFile failed to Create/Open: D:\\train_salsanet_2\\logs\\salsaNet_trained : Access is denied.\r\n; Input/output error\n\t [[{{node summary/saver/RestoreV2}}]]\n0 successful operations.\n0 derived errors ignored.\n\nOriginal stack trace for 'summary/saver/RestoreV2':\n  File \"C:\\Users\\mahdi\\anaconda3\\envs\\tf\\lib\\runpy.py\", line 197, in _run_module_as_main\n    return _run_code(code, main_globals, None,\n  File \"C:\\Users\\mahdi\\anaconda3\\envs\\tf\\lib\\runpy.py\", line 87, in _run_code\n    exec(code, run_globals)\n  File \"C:\\Users\\mahdi\\anaconda3\\envs\\tf\\lib\\site-packages\\ipykernel_launcher.py\", line 17, in <module>\n    app.launch_new_instance()\n  File \"C:\\Users\\mahdi\\anaconda3\\envs\\tf\\lib\\site-packages\\traitlets\\config\\application.py\", line 992, in launch_instance\n    app.start()\n  File \"C:\\Users\\mahdi\\anaconda3\\envs\\tf\\lib\\site-packages\\ipykernel\\kernelapp.py\", line 701, in start\n    self.io_loop.start()\n  File \"C:\\Users\\mahdi\\anaconda3\\envs\\tf\\lib\\site-packages\\tornado\\platform\\asyncio.py\", line 195, in start\n    self.asyncio_loop.run_forever()\n  File \"C:\\Users\\mahdi\\anaconda3\\envs\\tf\\lib\\asyncio\\windows_events.py\", line 321, in run_forever\n    super().run_forever()\n  File \"C:\\Users\\mahdi\\anaconda3\\envs\\tf\\lib\\asyncio\\base_events.py\", line 601, in run_forever\n    self._run_once()\n  File \"C:\\Users\\mahdi\\anaconda3\\envs\\tf\\lib\\asyncio\\base_events.py\", line 1905, in _run_once\n    handle._run()\n  File \"C:\\Users\\mahdi\\anaconda3\\envs\\tf\\lib\\asyncio\\events.py\", line 80, in _run\n    self._context.run(self._callback, *self._args)\n  File \"C:\\Users\\mahdi\\anaconda3\\envs\\tf\\lib\\site-packages\\ipykernel\\kernelbase.py\", line 534, in dispatch_queue\n    await self.process_one()\n  File \"C:\\Users\\mahdi\\anaconda3\\envs\\tf\\lib\\site-packages\\ipykernel\\kernelbase.py\", line 523, in process_one\n    await dispatch(*args)\n  File \"C:\\Users\\mahdi\\anaconda3\\envs\\tf\\lib\\site-packages\\ipykernel\\kernelbase.py\", line 429, in dispatch_shell\n    await result\n  File \"C:\\Users\\mahdi\\anaconda3\\envs\\tf\\lib\\site-packages\\ipykernel\\kernelbase.py\", line 767, in execute_request\n    reply_content = await reply_content\n  File \"C:\\Users\\mahdi\\anaconda3\\envs\\tf\\lib\\site-packages\\ipykernel\\ipkernel.py\", line 429, in do_execute\n    res = shell.run_cell(\n  File \"C:\\Users\\mahdi\\anaconda3\\envs\\tf\\lib\\site-packages\\ipykernel\\zmqshell.py\", line 549, in run_cell\n    return super().run_cell(*args, **kwargs)\n  File \"C:\\Users\\mahdi\\anaconda3\\envs\\tf\\lib\\site-packages\\IPython\\core\\interactiveshell.py\", line 3024, in run_cell\n    result = self._run_cell(\n  File \"C:\\Users\\mahdi\\anaconda3\\envs\\tf\\lib\\site-packages\\IPython\\core\\interactiveshell.py\", line 3079, in _run_cell\n    result = runner(coro)\n  File \"C:\\Users\\mahdi\\anaconda3\\envs\\tf\\lib\\site-packages\\IPython\\core\\async_helpers.py\", line 129, in _pseudo_sync_runner\n    coro.send(None)\n  File \"C:\\Users\\mahdi\\anaconda3\\envs\\tf\\lib\\site-packages\\IPython\\core\\interactiveshell.py\", line 3284, in run_cell_async\n    has_raised = await self.run_ast_nodes(code_ast.body, cell_name,\n  File \"C:\\Users\\mahdi\\anaconda3\\envs\\tf\\lib\\site-packages\\IPython\\core\\interactiveshell.py\", line 3466, in run_ast_nodes\n    if await self.run_code(code, result, async_=asy):\n  File \"C:\\Users\\mahdi\\anaconda3\\envs\\tf\\lib\\site-packages\\IPython\\core\\interactiveshell.py\", line 3526, in run_code\n    exec(code_obj, self.user_global_ns, self.user_ns)\n  File \"C:\\Users\\mahdi\\AppData\\Local\\Temp\\ipykernel_39624\\4024244953.py\", line 85, in <module>\n    main()\n  File \"C:\\Users\\mahdi\\AppData\\Local\\Temp\\ipykernel_39624\\4024244953.py\", line 71, in main\n    net = SegmenterNet(cfg, model_ckp_name)\n  File \"<string>\", line 40, in __init__\n  File \"<string>\", line 57, in init_network_model\n  File \"<string>\", line 127, in create_summary_ops\n  File \"C:\\Users\\mahdi\\anaconda3\\envs\\tf\\lib\\site-packages\\tensorflow\\python\\training\\saver.py\", line 931, in __init__\n    self.build()\n  File \"C:\\Users\\mahdi\\anaconda3\\envs\\tf\\lib\\site-packages\\tensorflow\\python\\training\\saver.py\", line 943, in build\n    self._build(self._filename, build_save=True, build_restore=True)\n  File \"C:\\Users\\mahdi\\anaconda3\\envs\\tf\\lib\\site-packages\\tensorflow\\python\\training\\saver.py\", line 971, in _build\n    self.saver_def = self._builder._build_internal(  # pylint: disable=protected-access\n  File \"C:\\Users\\mahdi\\anaconda3\\envs\\tf\\lib\\site-packages\\tensorflow\\python\\training\\saver.py\", line 540, in _build_internal\n    restore_op = self._AddRestoreOps(filename_tensor, saveables,\n  File \"C:\\Users\\mahdi\\anaconda3\\envs\\tf\\lib\\site-packages\\tensorflow\\python\\training\\saver.py\", line 360, in _AddRestoreOps\n    all_tensors = self.bulk_restore(filename_tensor, saveables, preferred_shard,\n  File \"C:\\Users\\mahdi\\anaconda3\\envs\\tf\\lib\\site-packages\\tensorflow\\python\\training\\saver.py\", line 608, in bulk_restore\n    return io_ops.restore_v2(filename_tensor, names, slices, dtypes)\n  File \"C:\\Users\\mahdi\\anaconda3\\envs\\tf\\lib\\site-packages\\tensorflow\\python\\ops\\gen_io_ops.py\", line 1516, in restore_v2\n    _, _, _op, _outputs = _op_def_library._apply_op_helper(\n  File \"C:\\Users\\mahdi\\anaconda3\\envs\\tf\\lib\\site-packages\\tensorflow\\python\\framework\\op_def_library.py\", line 797, in _apply_op_helper\n    op = g._create_op_internal(op_type_name, inputs, dtypes=None,\n  File \"C:\\Users\\mahdi\\anaconda3\\envs\\tf\\lib\\site-packages\\tensorflow\\python\\framework\\ops.py\", line 3800, in _create_op_internal\n    ret = Operation(\n"
     ]
    }
   ],
   "source": [
    "import import_ipynb\n",
    "from __future__ import print_function, division\n",
    "import os.path\n",
    "from config import *\n",
    "from utils import *\n",
    "from model import *\n",
    "from segmenter import SegmenterNet\n",
    "\n",
    "import matplotlib.pyplot as plt\n",
    "\n",
    "cfg = lidar_config()\n",
    "os.environ['CUDA_VISIBLE_DEVICES'] = str(cfg.GPU)\n",
    "print(\"creating network model using gpu \" + str(cfg.GPU))\n",
    "\n",
    "def test_with_bev_images (net, img):\n",
    "\n",
    "    with tf.compat.v1.Session(graph=net.graph) as sess:\n",
    "        net.initialize_vars(sess)\n",
    "\n",
    "        print(\"loading bev img \" + str(img))\n",
    "        lidar_data = np.load(img)\n",
    "        netInput = lidar_data[:,:,0:4] # mean, max, ref, den\n",
    "        netInput = netInput.astype('float32') / 255\n",
    "\n",
    "        pred_img = net.predict_single_image(input_img=netInput, session=sess)\n",
    "        print('predicted image shape: ', pred_img.shape, ' type: ',  pred_img.dtype, ' min val: ',  pred_img.min(), ' max val: ', pred_img.max())\n",
    "\n",
    "        showPredImg(pred_img)\n",
    "\n",
    "def test_with_point_cloud(net, cfg, cloud_path):\n",
    "\n",
    "    # load pc\n",
    "    pointCloud = np.load(cloud_path)\n",
    "\n",
    "    # define the region of interest for bird eye view image generation\n",
    "    pc2img = PC2ImgConverter(imgChannel=cfg.IMAGE_CHANNEL, xRange=[0, 50], yRange=[-6, 12], zRange=[-10, 8],\n",
    "                                                   xGridSize=0.2, yGridSize=0.3, zGridSize=0.3, maxImgHeight=cfg.IMAGE_HEIGHT,\n",
    "                                                   maxImgWidth=cfg.IMAGE_WIDTH, maxImgDepth=64)\n",
    "\n",
    "    bevImg, bevCloud = pc2img.getBEVImage(pointCloud)\n",
    "    bevImg = bevImg.astype('float32') / 255\n",
    "    print('bird eye view image shape: ', bevImg.shape)\n",
    "\n",
    "    with tf.compat.v1.Session(graph=net.graph) as sess:\n",
    "        net.initialize_vars(sess)\n",
    "\n",
    "        pred_img = net.predict_single_image(input_img=bevImg, session=sess)\n",
    "        print('predicted image shape: ', pred_img.shape, ' type: ', pred_img.dtype, ' min val: ', pred_img.min(),\n",
    "              ' max val: ', pred_img.max())\n",
    "\n",
    "\n",
    "        roadCloud, vehicleCloud = pc2img.getCloudsFromBEVImage(pred_img, bevCloud, postProcessing=True)\n",
    "\n",
    "        showPredImg(pred_img)\n",
    "\n",
    "def showPredImg(img=[]):\n",
    "\n",
    "    plt.imshow(img)\n",
    "    plt.axis('off')\n",
    "\n",
    "    plt.show()\n",
    "\n",
    "def main():\n",
    "\n",
    "    # get config params\n",
    "    cfg = lidar_config()\n",
    "\n",
    "    # get trained model checkpoints\n",
    "    model_ckp_name = r\"D:\\train_salsanet_2\\logs\\salsaNet_trained\"\n",
    "    # load the trained model\n",
    "    net = SegmenterNet(cfg, model_ckp_name)\n",
    "\n",
    "    # testing with the already created bird eye view images\n",
    "    test_bev_img = \"C:/Users/mahdi/test_bev_image.npy\"\n",
    "    test_with_bev_images(net, test_bev_img)\n",
    "\n",
    "    # testing by using the raw point cloud data\n",
    "    #test_cloud = \"../data/test_cloud.npy\"\n",
    "    #test_with_point_cloud(net, cfg, test_cloud)\n",
    "\n",
    "    return\n",
    "\n",
    "if __name__ == '__main__':\n",
    "\n",
    "    main()\n"
   ]
  },
  {
   "cell_type": "code",
   "execution_count": null,
   "id": "8c1b8675-0003-4437-b9d4-2c98ad223a90",
   "metadata": {},
   "outputs": [],
   "source": []
  }
 ],
 "metadata": {
  "kernelspec": {
   "display_name": "Python 3 (ipykernel)",
   "language": "python",
   "name": "python3"
  },
  "language_info": {
   "codemirror_mode": {
    "name": "ipython",
    "version": 3
   },
   "file_extension": ".py",
   "mimetype": "text/x-python",
   "name": "python",
   "nbconvert_exporter": "python",
   "pygments_lexer": "ipython3",
   "version": "3.9.19"
  }
 },
 "nbformat": 4,
 "nbformat_minor": 5
}
